Workbook
Name Costco_COGS: 'Raw Data'!$C$29:$M$29
Name Costco_CurrentAssets: 'Raw Data'!$C$31:$M$31
Name Costco_CurrentLiabilities: 'Raw Data'!$C$32:$M$32
Name Costco_Inventory: 'Raw Data'!$C$43:$M$43
Name Costco_LIFOReserve: 'Raw Data'!$C$44:$M$44
Name Costco_MembershipFeeRevenueIncluded_FY2025: 'Raw Data'!$D$110
Name Costco_MembershipFees: 'Raw Data'!$C$46:$M$46
Name Costco_NetIncome: 'Raw Data'!$C$30:$M$30
Name Costco_OperatingIncome: 'Raw Data'!$C$40:$M$40
Name Costco_OperatingLease: 'Raw Data'!$C$41:$M$41
Name Costco_Revenue: 'Raw Data'!$C$28:$M$28
Name Costco_TotalAssets: 'Raw Data'!$C$42:$M$42
Name Costco_TotalDebt: 'Raw Data'!$C$34:$M$34
Name Costco_TotalEquity: 'Raw Data'!$C$33:$M$33
Name Costco_TotalRevenue: 'Raw Data'!$C$45:$M$45
Name CR_Costco: 'Ratio Calculations'!$B$29:$K$29
Name CR_Kroger: 'Ratio Calculations'!$B$30:$K$30
Name CR_SamsClub: 'Ratio Calculations'!$B$31:$K$31
Name CR_Walmart: 'Ratio Calculations'!$B$28:$K$28
Name CR_WholeFoods: 'Ratio Calculations'!$B$32:$K$32
Name DE_Costco: 'Ratio Calculations'!$B$36:$K$36
Name DE_Kroger: 'Ratio Calculations'!$B$37:$K$37
Name DE_SamsClub: 'Ratio Calculations'!$B$38:$K$38
Name DE_Walmart: 'Ratio Calculations'!$B$35:$K$35
Name DE_WholeFoods: 'Ratio Calculations'!$B$39:$K$39
Name DEL_Costco: 'Ratio Calculations'!$B$43:$K$43
Name DEL_Kroger: 'Ratio Calculations'!$B$44:$K$44
Name DEL_SamsClub: 'Ratio Calculations'!$B$45:$K$45
Name DEL_Walmart: 'Ratio Calculations'!$B$42:$K$42
Name DEL_WholeFoods: 'Ratio Calculations'!$B$46:$K$46
Name GM_Costco: 'Ratio Calculations'!$B$8:$K$8
Name GM_Kroger: 'Ratio Calculations'!$B$9:$K$9
Name GM_SamsClub: 'Ratio Calculations'!$B$10:$K$10
Name GM_Walmart: 'Ratio Calculations'!$B$7:$K$7
Name GM_WholeFoods: 'Ratio Calculations'!$B$11:$K$11
Name GR_Costco: 'Ratio Calculations'!$B$50:$K$50
Name GR_Kroger: 'Ratio Calculations'!$B$51:$K$51
Name GR_SamsClub: 'Ratio Calculations'!$B$52:$K$52
Name GR_Walmart: 'Ratio Calculations'!$B$49:$K$49
Name GR_WholeFoods: 'Ratio Calculations'!$B$53:$K$53
Name Kroger_COGS: 'Raw Data'!$C$51:$M$51
Name Kroger_CurrentAssets: 'Raw Data'!$C$53:$M$53
Name Kroger_CurrentLiabilities: 'Raw Data'!$C$54:$M$54
Name Kroger_LIFOReserve: 'Raw Data'!$C$67:$M$67
Name Kroger_LifoReserve_FY2016: 'Raw Data'!$D$108
Name Kroger_LifoReserve_FY2025: 'Raw Data'!$D$107
Name Kroger_NetIncome: 'Raw Data'!$C$52:$M$52
Name Kroger_OperatingIncome: 'Raw Data'!$C$64:$M$64
Name Kroger_OperatingLease: 'Raw Data'!$C$65:$M$65
Name Kroger_ProceedsFromIssuanceOf_FY2024: 'Raw Data'!$D$103
Name Kroger_RestructuringAndAssetImpairment_FY2025: 'Raw Data'!$D$106
Name Kroger_Revenue: 'Raw Data'!$C$50:$M$50
Name Kroger_ShareRepurchases_FY2024: 'Raw Data'!$D$104
Name Kroger_ShareRepurchases_FY2025: 'Raw Data'!$D$105
Name Kroger_TotalAssets: 'Raw Data'!$C$66:$M$66
Name Kroger_TotalDebt: 'Raw Data'!$C$56:$M$56
Name Kroger_TotalEquity: 'Raw Data'!$C$55:$M$55
Name NM_Costco: 'Ratio Calculations'!$B$22:$K$22
Name NM_Kroger: 'Ratio Calculations'!$B$23:$K$23
Name NM_SamsClub: 'Ratio Calculations'!$B$24:$K$24

Sheet Cover
B2: LOGO
C3: 01 — COVER · COMPETITOR SCORECARD · FY2016–FY2025 · SEC 10-K DATA
B7: Competitor Scorecard:
B8: Walmart, Costco, Kroger & Sam's Club
B9: with Whole Foods Market on a best-effort basis
B11: Ten-year financial comparison (FY2016–FY2025) built from SEC 10-K filings: capital structure, resilience through 2020–2023, and margin pressure — every ratio a live formula traceable to its XBRL fact.
B13: Prepared by | C13: Ryan Barry
B14: Date | C14: September 18, 2026
B15: Data source | C15: SEC EDGAR – 10-K XBRL filings (companyfacts API and instance documents)
B16: Coverage | C16: Walmart Inc. · Costco Wholesale Corp. · The Kroger Co. – full 10-K coverage FY2016–FY2025
C17: Sam's Club – Walmart reportable segment (ASC 280): sales, operating income, assets; cost of sales FY2022+
C18: Whole Foods Market – standalone 10-Ks FY2016–FY2017; Amazon 'Physical stores' net sales thereafter
B19: Units | C19: USD millions unless stated; fiscal years labelled by SEC frame convention (see Methodology)
B20: Status | C20: All formulas live; recalculated in Excel with zero formula errors
B22: Contents
B23: Executive Summary | C23: Findings against the three key questions, trend shifts, data caveats
B24: Raw Data | C24: As-reported inputs by company and year, named ranges, SEC citations, debt build
B25: Ratio Calculations | C25: Gross margin, operating margin, net margin, current ratio, debt-to-equity, revenue growth
B26: Scorecard | C26: Latest-year ranking per metric with conditional formatting and takeaways
B27: Trend | C27: Native line charts FY2016–FY2025 with the FY2020–FY2023 shock window shaded
B28: Methodology & Tools | C28: Sources, techniques, accounting-policy comparability, assumptions
B29: Data Lineage | C29: Every input value with XBRL tag, accession number, filing date and restatement flag
B31: Personal portfolio project built from public filings only. Not an H-E-B work product; no non-public information used.

Sheet Executive Summary
B1: COMPETITOR SCORECARD · FY2016–FY2025 · SEC 10-K DATA
B2: Executive Summary
B3: Findings are stated against the three key questions. Every figure quoted below is a live formula into the Ratio Calculations and Raw Data tabs; cited transactions (debt issued, buybacks, charges) are on Raw Data under 'Supporting facts'.
B4: 1. Capital structure & financing strategy — who is financed most conservatively, and has that changed?
B5: BOTTOM LINE: Costco is the most conservatively financed of the group and has become more so every year since FY2021. Walmart's leverage is unchanged over the decade. Kroger has nearly tripled its debt-to-equity since FY2023 to fund share repurchases after the Albertsons merger collapsed – a deliberate capital-return decision, but the one red flag in the set.
B6: ="• Costco is financed most conservatively and is still de-levering: debt-to-equity fell from "&TEXT(_xlfn.XLOOKUP(2016,RatioYears,DE_Costco),"0.00")&"x"&" in FY2016 to "&TEXT(_xlfn.XLOOKUP(2025,RatioYears,DE_Costco),"0.00")&"x"&" in FY2025. Total debt has stayed near "&"$"&TEXT(_xlfn.XLOOKUP(2025,Years,Costco_TotalDebt)/1000,"0.0")&"B"&" while equity compounded from "&"$"&TEXT(_xlfn.XLOOKUP(2016,Years,Costco_TotalEquity)/1000,"0.0")&"B"&" to "&"$"&TEXT(_xlfn.XLOOKUP(2025,Years,Costco_TotalEquity)/1000,"0.0")&"B"&" – growth and buybacks are funded from operating cash flow, not borrowing." -> • Costco is financed most conservatively and is still de-levering: debt-to-equity fell from 0.45x in FY2016 to 0.25x in FY2025. Total debt has stayed near $7.3B while equity compounded from $12.3B to $29.2B – growth and buybacks are funded from operating cash flow, not borrowing.
B7: ="• Walmart is stable by design: debt-to-equity has held in a "&TEXT(MIN(DE_Walmart),"0.00")&"x"&"–"&TEXT(MAX(DE_Walmart),"0.00")&"x"&" band for the whole decade. Total debt in FY2025 ("&"$"&TEXT(_xlfn.XLOOKUP(2025,Years,Walmart_TotalDebt)/1000,"0.0")&"B"&") is only "&TEXT(_xlfn.XLOOKUP(2025,Years,Walmart_TotalDebt)/_xlfn.XLOOKUP(2016,Years,Walmart_TotalDebt)-1,"0.0%")&" above FY2016 ("&"$"&TEXT(_xlfn.XLOOKUP(2016,Years,Walmart_TotalDebt)/1000,"0.0")&"B"&") on revenue that is "&TEXT(_xlfn.XLOOKUP(2025,Years,Walmart_Revenue)/_xlfn.XLOOKUP(2016,Years,Walmart_Revenue)-1,"0.0%")&" larger, so leverage has fallen relative to the size of the business." -> • Walmart is stable by design: debt-to-equity has held in a 0.47x–0.73x band for the whole decade. Total debt in FY2025 ($51.5B) is only 12.2% above FY2016 ($45.9B) on revenue that is 46.8% larger, so leverage has fallen relative to the size of the business.
B8: ="• Kroger is the outlier and the one genuine red flag. It de-levered from "&TEXT(_xlfn.XLOOKUP(2016,RatioYears,DE_Kroger),"0.00")&"x"&" (FY2016) to "&TEXT(_xlfn.XLOOKUP(2023,RatioYears,DE_Kroger),"0.00")&"x"&" (FY2023), then re-levered to "&TEXT(_xlfn.XLOOKUP(2024,RatioYears,DE_Kroger),"0.00")&"x"&" in FY2024 and "&TEXT(_xlfn.XLOOKUP(2025,RatioYears,DE_Kroger),"0.00")&"x"&" in FY2025. The FY2024 10-K shows "&"$"&TEXT(Kroger_ProceedsFromIssuanceOf_FY2024/1000,"0.0")&"B"&" of long-term debt issued for the Albertsons merger (terminated December 2024) and "&"$"&TEXT(Kroger_ShareRepurchases_FY2024/1000,"0.0")&"B"&" of share repurchases, followed by a further "&"$"&TEXT(Kroger_ShareRepurchases_FY2025/1000,"0.0")&"B"&" of repurchases in FY2025; equity fell from "&"$"&TEXT(_xlfn.XLOOKUP(2023,Years,Kroger_TotalEquity)/1000,"0.0")&"B"&" to "&"$"&TEXT(_xlfn.XLOOKUP(2025,Years,Kroger_TotalEquity)/1000,"0.0")&"B"&" in two years." -> • Kroger is the outlier and the one genuine red flag. It de-levered from 2.10x (FY2016) to 1.05x (FY2023), then re-levered to 2.16x in FY2024 and 2.96x in FY2025. The FY2024 10-K shows $10.5B of long-term debt issued for the Albertsons merger (terminated December 2024) and $4.2B of share repurchases, followed by a further $2.7B of repurchases in FY2025; equity fell from $11.6B to $5.9B in two years.
B9: =_xlfn._LONGTEXT("• Reading: Kroger's leverage is funding buybacks, not growth – revenue has been flat since FY2022 – and it is doing so on an equity base shrunk by charges. That is a deliberate capital-return choice, but it leaves the least financial flexibility in the gr","oup and would be the first balance sheet to strain if margins slip further.") -> • Reading: Kroger's leverage is funding buybacks, not growth – revenue has been flat since FY2022 – and it is doing so on an equity base shrunk by charges. That is a deliberate capital-return choice, but it leaves the least financial flexibility in the group and would be the first balance sheet to strain if margins slip further.
B10: ="• Lease-adjusted view (ASC 842): including operating lease liabilities lifts every ratio but changes no ranking – FY2025 debt-to-equity incl. leases is "&TEXT(_xlfn.XLOOKUP(2025,RatioYears,DEL_Costco),"0.00")&"x"&" Costco, "&TEXT(_xlfn.XLOOKUP(2025,RatioYears,DEL_Walmart),"0.00")&"x"&" Walmart, "&TEXT(_xlfn.XLOOKUP(2025,RatioYears,DEL_Kroger),"0.00")&"x"&" Kroger." -> • Lease-adjusted view (ASC 842): including operating lease liabilities lifts every ratio but changes no ranking – FY2025 debt-to-equity incl. leases is 0.34x Costco, 0.63x Walmart, 4.16x Kroger.
B12: 2. Resilience through 2020–2023 — who absorbed COVID and the inflation spike best, and who took the biggest hit?
B13: BOTTOM LINE: Costco absorbed the shock best – revenue, net margin and liquidity all rose through the window. Walmart took the biggest hit, with FY2022 gross and operating margins the lowest of the decade, but recovered within two years. Kroger's margin swings were fuel-mix effects, not financial stress.
B14: ="• Costco absorbed the shock best. Revenue grew "&TEXT(_xlfn.XLOOKUP(2020,RatioYears,GR_Costco),"0.0%")&", "&TEXT(_xlfn.XLOOKUP(2021,RatioYears,GR_Costco),"0.0%")&" and "&TEXT(_xlfn.XLOOKUP(2022,RatioYears,GR_Costco),"0.0%")&" in FY2020–FY2022; net margin rose from "&TEXT(_xlfn.XLOOKUP(2019,RatioYears,NM_Costco),"0.0%")&" (FY2019) to "&TEXT(_xlfn.XLOOKUP(2023,RatioYears,NM_Costco),"0.0%")&" (FY2023); the current ratio peaked at "&TEXT(_xlfn.XLOOKUP(2020,RatioYears,CR_Costco),"0.00")&"x"&" in FY2020 and never fell below "&TEXT(MIN(CR_Costco),"0.00")&"x"&". Gross margin dipped to "&TEXT(_xlfn.XLOOKUP(2022,RatioYears,GM_Costco),"0.0%")&" in FY2022 – inflation absorbed on members' behalf – and has since recovered to "&TEXT(_xlfn.XLOOKUP(2025,RatioYears,GM_Costco),"0.0%")&"." -> • Costco absorbed the shock best. Revenue grew 9.3%, 17.7% and 16.0% in FY2020–FY2022; net margin rose from 2.4% (FY2019) to 2.6% (FY2023); the current ratio peaked at 1.13x in FY2020 and never fell below 0.97x. Gross margin dipped to 10.5% in FY2022 – inflation absorbed on members' behalf – and has since recovered to 11.1%.
B15: ="• Walmart took the biggest single-year hit, in FY2022 (year ended January 2023): gross margin fell to "&TEXT(_xlfn.XLOOKUP(2022,RatioYears,GM_Walmart),"0.0%")&" and operating margin to "&TEXT(_xlfn.XLOOKUP(2022,RatioYears,OM_Walmart),"0.0%")&", the lowest of the decade, as inventory built and was marked down; the current ratio fell from "&TEXT(_xlfn.XLOOKUP(2020,RatioYears,CR_Walmart),"0.00")&"x"&" (FY2020) to "&TEXT(_xlfn.XLOOKUP(2022,RatioYears,CR_Walmart),"0.00")&"x"&". Recovery was quick – operating margin was back to "&TEXT(_xlfn.XLOOKUP(2024,RatioYears,OM_Walmart),"0.0%")&" by FY2024 and net margin to "&TEXT(_xlfn.XLOOKUP(2025,RatioYears,NM_Walmart),"0.0%")&" in FY2025." -> • Walmart took the biggest single-year hit, in FY2022 (year ended January 2023): gross margin fell to 23.5% and operating margin to 3.4%, the lowest of the decade, as inventory built and was marked down; the current ratio fell from 0.97x (FY2020) to 0.82x. Recovery was quick – operating margin was back to 4.4% by FY2024 and net margin to 3.1% in FY2025.
B16: ="• Kroger's margins moved most but for a mix reason: gross margin jumped to "&TEXT(_xlfn.XLOOKUP(2020,RatioYears,GM_Kroger),"0.0%")&" in FY2020 when low-margin fuel sales collapsed, then fell to "&TEXT(_xlfn.XLOOKUP(2022,RatioYears,GM_Kroger),"0.0%")&" in FY2022 as fuel prices spiked. Through FY2020–FY2023 net margin stayed between "&TEXT(MIN(INDEX(NM_Kroger,1,5):INDEX(NM_Kroger,1,8)),"0.0%")&" and "&TEXT(MAX(INDEX(NM_Kroger,1,5):INDEX(NM_Kroger,1,8)),"0.0%")&", and the current ratio ("&TEXT(MIN(INDEX(CR_Kroger,1,5):INDEX(CR_Kroger,1,8)),"0.00")&"x"&"–"&TEXT(MAX(INDEX(CR_Kroger,1,5):INDEX(CR_Kroger,1,8)),"0.00")&"x"&") is structurally the lowest of the three – a feature of its working-capital model, not a shock effect." -> • Kroger's margins moved most but for a mix reason: gross margin jumped to 23.3% in FY2020 when low-margin fuel sales collapsed, then fell to 21.4% in FY2022 as fuel prices spiked. Through FY2020–FY2023 net margin stayed between 1.2% and 2.0%, and the current ratio (0.74x–0.81x) is structurally the lowest of the three – a feature of its working-capital model, not a shock effect.
B17: ="• Sam's Club (segment) grew net sales "&TEXT(_xlfn.XLOOKUP(2020,RatioYears,GR_SamsClub),"0.0%")&", "&TEXT(_xlfn.XLOOKUP(2021,RatioYears,GR_SamsClub),"0.0%")&" and "&TEXT(_xlfn.XLOOKUP(2022,RatioYears,GR_SamsClub),"0.0%")&" over FY2020–FY2022 with operating margin between "&TEXT(MIN(INDEX(OM_SamsClub,1,5):INDEX(OM_SamsClub,1,8)),"0.0%")&" and "&TEXT(MAX(INDEX(OM_SamsClub,1,5):INDEX(OM_SamsClub,1,8)),"0.0%")&" through FY2020–FY2023 – the club format was the clear beneficiary of pandemic-era bulk buying and inflation trade-down." -> • Sam's Club (segment) grew net sales 8.7%, 15.1% and 14.7% over FY2020–FY2022 with operating margin between 2.3% and 3.1% through FY2020–FY2023 – the club format was the clear beneficiary of pandemic-era bulk buying and inflation trade-down.
B19: 3. Margin pressure since 2016 — who has felt it most, and is it cost, pricing, or mix?
B20: BOTTOM LINE: Walmart has felt the most persistent pressure, and it is pricing and mix – gross margin gave up ground while SG&A held. Kroger's decline is the steepest in operating terms but sits below gross profit: cost growth and FY2025 one-off charges, not pricing. Costco shows no pressure at all; Sam's Club's margin is improving.
B21: ="• Walmart shows the most persistent pressure among the full filers: gross margin "&TEXT(_xlfn.XLOOKUP(2016,RatioYears,GM_Walmart),"0.0%")&" (FY2016) → "&TEXT(_xlfn.XLOOKUP(2022,RatioYears,GM_Walmart),"0.0%")&" (FY2022 low) → "&TEXT(_xlfn.XLOOKUP(2025,RatioYears,GM_Walmart),"0.0%")&" (FY2025), and operating margin "&TEXT(_xlfn.XLOOKUP(2016,RatioYears,OM_Walmart),"0.0%")&" → "&TEXT(_xlfn.XLOOKUP(2025,RatioYears,OM_Walmart),"0.0%")&". The driver is pricing and mix, not cost: the gross-margin give-up tracks Walmart's stated price investment and the shift toward lower-margin e-commerce and grocery, while the operating-margin gap to gross margin has not widened – SG&A is under control." -> • Walmart shows the most persistent pressure among the full filers: gross margin 24.9% (FY2016) → 23.5% (FY2022 low) → 24.2% (FY2025), and operating margin 4.7% → 4.2%. The driver is pricing and mix, not cost: the gross-margin give-up tracks Walmart's stated price investment and the shift toward lower-margin e-commerce and grocery, while the operating-margin gap to gross margin has not widened – SG&A is under control.
B22: ="• Kroger's decline is the largest in operating terms – "&TEXT(_xlfn.XLOOKUP(2016,RatioYears,OM_Kroger),"0.0%")&" in FY2016 to "&TEXT(_xlfn.XLOOKUP(2025,RatioYears,OM_Kroger),"0.0%")&" in FY2025 – but the FY2025 figure includes "&"$"&TEXT(Kroger_RestructuringAndAssetImpairment_FY2025/1000,"0.0")&"B"&" of restructuring and asset-impairment charges; excluding them, operating margin would be about "&TEXT((_xlfn.XLOOKUP(2025,Years,Kroger_OperatingIncome)+Kroger_RestructuringAndAssetImpairment_FY2025)/_xlfn.XLOOKUP(2025,Years,Kroger_Revenue),"0.0%")&". Its gross margin is essentially unchanged ("&TEXT(_xlfn.XLOOKUP(2016,RatioYears,GM_Kroger),"0.0%")&" → "&TEXT(_xlfn.XLOOKUP(2025,RatioYears,GM_Kroger),"0.0%")&"), so the pressure is below gross profit: cost (labour, D&A) and one-off charges rather than pricing." -> • Kroger's decline is the largest in operating terms – 3.0% in FY2016 to 1.3% in FY2025 – but the FY2025 figure includes $2.7B of restructuring and asset-impairment charges; excluding them, operating margin would be about 3.1%. Its gross margin is essentially unchanged (22.4% → 23.3%), so the pressure is below gross profit: cost (labour, D&A) and one-off charges rather than pricing.
B23: ="• Costco shows no pressure: gross margin is flat by design ("&TEXT(_xlfn.XLOOKUP(2016,RatioYears,GM_Costco),"0.0%")&" → "&TEXT(_xlfn.XLOOKUP(2025,RatioYears,GM_Costco),"0.0%")&") while net margin expanded from "&TEXT(_xlfn.XLOOKUP(2016,RatioYears,NM_Costco),"0.0%")&" to "&TEXT(_xlfn.XLOOKUP(2025,RatioYears,NM_Costco),"0.0%")&" – membership fees ("&"$"&TEXT(Costco_MembershipFeeRevenueIncluded_FY2025/1000,"0.0")&"B"&" in FY2025, equal to "&TEXT(Costco_MembershipFeeRevenueIncluded_FY2025/_xlfn.XLOOKUP(2025,Years,Costco_Revenue),"0.0%")&" of net sales, excluded from net sales here and carrying no cost of sales) and operating leverage on "&TEXT(_xlfn.XLOOKUP(2025,Years,Costco_Revenue)/_xlfn.XLOOKUP(2016,Years,Costco_Revenue)-1,"0.0%")&" cumulative revenue growth." -> • Costco shows no pressure: gross margin is flat by design (11.3% → 11.1%) while net margin expanded from 2.0% to 3.0% – membership fees ($5.3B in FY2025, equal to 2.0% of net sales, excluded from net sales here and carrying no cost of sales) and operating leverage on 132.5% cumulative revenue growth.
B24: ="• Sam's Club is improving: segment gross margin rose from "&TEXT(_xlfn.XLOOKUP(2022,RatioYears,GM_SamsClub),"0.0%")&" (FY2022) to "&TEXT(_xlfn.XLOOKUP(2025,RatioYears,GM_SamsClub),"0.0%")&" (FY2025) – a mix shift toward members-only pricing and away from fuel. Whole Foods was already under pricing pressure before the Amazon deal: gross margin "&TEXT(_xlfn.XLOOKUP(2016,RatioYears,GM_WholeFoods),"0.0%")&" → "&TEXT(_xlfn.XLOOKUP(2017,RatioYears,GM_WholeFoods),"0.0%")&" and operating margin "&TEXT(_xlfn.XLOOKUP(2016,RatioYears,OM_WholeFoods),"0.0%")&" → "&TEXT(_xlfn.XLOOKUP(2017,RatioYears,OM_WholeFoods),"0.0%")&" in its last two standalone years." -> • Sam's Club is improving: segment gross margin rose from 10.4% (FY2022) to 11.3% (FY2025) – a mix shift toward members-only pricing and away from fuel. Whole Foods was already under pricing pressure before the Amazon deal: gross margin 34.4% → 33.7% and operating margin 5.5% → 2.9% in its last two standalone years.
B26: Notable trend shifts since FY2016
B27: ="• Costco's step-change: revenue growth of "&TEXT(_xlfn.XLOOKUP(2021,RatioYears,GR_Costco),"0.0%")&" and "&TEXT(_xlfn.XLOOKUP(2022,RatioYears,GR_Costco),"0.0%")&" in FY2021–FY2022 lifted it from "&"$"&TEXT(_xlfn.XLOOKUP(2016,Years,Costco_Revenue)/1000,"0.0")&"B"&" to "&"$"&TEXT(_xlfn.XLOOKUP(2025,Years,Costco_Revenue)/1000,"0.0")&"B"&" – it is now "&TEXT(_xlfn.XLOOKUP(2025,Years,Costco_Revenue)/_xlfn.XLOOKUP(2025,Years,Kroger_Revenue),"0.0")&"x Kroger's size, versus "&TEXT(_xlfn.XLOOKUP(2016,Years,Costco_Revenue)/_xlfn.XLOOKUP(2016,Years,Kroger_Revenue),"0.0")&"x in FY2016." -> • Costco's step-change: revenue growth of 17.7% and 16.0% in FY2021–FY2022 lifted it from $116.1B to $269.9B – it is now 1.8x Kroger's size, versus 1.0x in FY2016.
B28: ="• Kroger's reversal: five years of de-leveraging (FY2018–FY2023) undone in two. Debt-to-equity "&TEXT(_xlfn.XLOOKUP(2023,RatioYears,DE_Kroger),"0.00")&"x"&" → "&TEXT(_xlfn.XLOOKUP(2025,RatioYears,DE_Kroger),"0.00")&"x"&"; revenue "&TEXT(_xlfn.XLOOKUP(2024,RatioYears,GR_Kroger),"0.0%")&" and "&TEXT(_xlfn.XLOOKUP(2025,RatioYears,GR_Kroger),"0.0%")&" in FY2024–FY2025." -> • Kroger's reversal: five years of de-leveraging (FY2018–FY2023) undone in two. Debt-to-equity 1.05x → 2.96x; revenue -1.9% and 0.4% in FY2024–FY2025.
B29: ="• ASC 842 (FY2019; Costco FY2020) put operating leases on every balance sheet. Total debt in this model excludes them so FY2016–FY2018 remain comparable; the supplementary lease-inclusive ratio shows the effect." -> • ASC 842 (FY2019; Costco FY2020) put operating leases on every balance sheet. Total debt in this model excludes them so FY2016–FY2018 remain comparable; the supplementary lease-inclusive ratio shows the effect.
B31: Data caveats
B32: • Sam's Club is a reportable segment of Walmart (ASC 280), not a filer: net sales, operating income and total assets are available FY2016–FY2025; cost of revenue only from FY2022 (ASU 2023-07 comparatives); no net income, current ratio or debt is reported at segment level.
B33: • Whole Foods Market filed its last 10-K for FY2017 (acquired by Amazon.com 2017-08-28). FY2018 onward the only public figure is Amazon's 'Physical stores' net sales, which also includes Amazon Fresh and Amazon Go. Whole Foods' cost line included occupancy costs, so its ~34% gross margin is not like-for-like with peers.
B34: ="• Inventory method: Walmart (U.S.), Costco (U.S.) and Kroger (~91% of inventory) use LIFO; Whole Foods used LIFO; Costco Canada / Walmart International use FIFO. Kroger discloses its LIFO reserve – "&"$"&TEXT(Kroger_LifoReserve_FY2025/1000,"0.0")&"B"&" at FY2025 versus "&"$"&TEXT(Kroger_LifoReserve_FY2016/1000,"0.0")&"B"&_xlfn._LONGTEXT(" at FY2016 – so its reported inventory and cost of sales understate FIFO-basis values. Walmart disclosed that LIFO approximated FIFO through January 2022 and gives only sensitivity language since; Costco discloses no reserve but took a LIFO charge worth 1","9 bp of gross margin in FY2022. Gross margins are therefore compared as reported; a full FIFO restatement is outside this workbook's scope and is discussed on the Methodology tab.") -> • Inventory method: Walmart (U.S.), Costco (U.S.) and Kroger (~91% of inventory) use LIFO; Whole Foods used LIFO; Costco Canada / Walmart International use FIFO. Kroger discloses its LIFO reserve – $2.6B at FY2025 versus $1.3B at FY2016 – so its reported inventory and cost of sales understate FIFO-basis values. Walmart disclosed that LIFO approximated FIFO through January 2022 and gives only sensitivity language since; Costco discloses no reserve but took a LIFO charge worth 19 bp of gross margin in FY2022. Gross margins are therefore compared as reported; a full FIFO restatement is outside this workbook's scope and is discussed on the Methodology tab.
B35: ="• Total equity includes noncontrolling interests (Walmart: "&"$"&TEXT(Walmart_NoncontrollingInterestInTotal_FY2025/1000,"0.0")&"B"&" at FY2025) while net income is the amount attributable to the parent – the standard presentation, but it slightly lowers Walmart's debt-to-equity relative to a parent-only basis." -> • Total equity includes noncontrolling interests (Walmart: $6.3B at FY2025) while net income is the amount attributable to the parent – the standard presentation, but it slightly lowers Walmart's debt-to-equity relative to a parent-only basis.
B36: • 53-week fiscal years: Costco and Kroger FY2017 and FY2023 each contain 53 weeks (371 days), which flatters growth in those years and depresses it the year after by roughly 2 percentage points. Fiscal years are aligned by the SEC frame convention (calendar year holding most of the period), so Walmart's 'fiscal 2026' (ended January 2026) is FY2025 here.
B37: • Every input carries its XBRL tag, accession number and filing date on the Data Lineage tab; seven values the SEC API could not return were taken from the filing's XBRL instance or derived from two tagged facts and are shaded yellow on Raw Data.

Sheet Raw Data
A1: 03 — RAW DATA | N1: COMPETITOR SCORECARD · FY2016–FY2025 · SEC 10-K DATA
A2: Raw Data
A3: As reported in SEC 10-K filings. USD millions. Blue = hard-coded input from EDGAR XBRL (one citation per value on the Data Lineage tab); black = formula; 'n/a' = not reported – flagged, never estimated. Fiscal years labelled by SEC frame convention (FY2025 = Walmart fiscal 2026, Kroger 2025, Costco 2025).
A4: Line item | B4: XBRL tag(s) / basis | C4: 2015 | D4: 2016 | E4: 2017 | F4: 2018 | G4: 2019 | H4: 2020 | I4: 2021 | J4: 2022 | K4: 2023 | L4: 2024 | M4: 2025 | N4: Source / notes
A6: Walmart — Walmart Inc., CIK 104169
A7: Fiscal year end | B7: January 31 | C7: 42400 | D7: 42766 | E7: 43131 | F7: 43496 | G7: 43861 | H7: 44227 | I7: 44592 | J7: 44957 | K7: 45322 | L7: 45688 | M7: 46053
A8: Revenue (net sales) | B8: RevenueFromContractWithCustomerExcludingAssessedTax; SalesRevenueNet | C8: 478614 | D8: 481317 | E8: 495761 | F8: 510329 | G8: 519926 | H8: 555233 | I8: 567762 | J8: 605881 | K8: 642637 | L8: 674538 | M8: 706413 | N8: 10-K XBRL via SEC companyfacts API; latest-filed (restated) value.
A9: Cost of sales | B9: CostOfRevenue | C9: 360984 | D9: 361256 | E9: 373396 | F9: 385301 | G9: 394605 | H9: 420315 | I9: 429000 | J9: 463721 | K9: 490142 | L9: 511753 | M9: 535395 | N9: 10-K XBRL via SEC companyfacts API; latest-filed (restated) value.
A10: Net income | B10: NetIncomeLoss | C10: 14694 | D10: 13643 | E10: 9862 | F10: 6670 | G10: 14881 | H10: 13510 | I10: 13673 | J10: 11680 | K10: 15511 | L10: 19436 | M10: 21893 | N10: 10-K XBRL via SEC companyfacts API; latest-filed (restated) value. Attributable to the parent (NetIncomeLoss).
A11: Current assets | B11: AssetsCurrent | C11: 60239 | D11: 57689 | E11: 59664 | F11: 61897 | G11: 61806 | H11: 90067 | I11: 81070 | J11: 75655 | K11: 76877 | L11: 79458 | M11: 84874 | N11: 10-K XBRL via SEC companyfacts API; latest-filed (restated) value.
A12: Current liabilities | B12: LiabilitiesCurrent | C12: 64619 | D12: 66928 | E12: 78521 | F12: 77477 | G12: 77790 | H12: 92645 | I12: 87379 | J12: 92198 | K12: 92415 | L12: 96584 | M12: 107469 | N12: 10-K XBRL via SEC companyfacts API; latest-filed (restated) value.
A13: Total equity (incl. noncontrolling interest) | B13: StockholdersEquityIncludingPortionAttributableToNoncontrollingInterest | C13: 83611 | D13: 80535 | E13: 80822 | F13: 79634 | G13: 81552 | H13: 87531 | I13: 91891 | J13: 83754 | K13: 90349 | L13: 97421 | M13: 105887 | N13: 10-K XBRL via SEC companyfacts API; latest-filed (restated) value. Includes noncontrolling interest (Walmart FY2025: $6.3B).
A14: Total debt (formula – see debt build below) | B14: Policy: config/debt_policy.yaml (ASC 842) | C14: =SUM(C15,C16,C17)+IF(COUNT(C18,C19)>0,SUM(C18,C19),IF(ISNUMBER(C20),C20,0)) -> 50034 | D14: =SUM(D15,D16,D17)+IF(COUNT(D18,D19)>0,SUM(D18,D19),IF(ISNUMBER(D20),D20,0)) -> 45938 | E14: =SUM(E15,E16,E17)+IF(COUNT(E18,E19)>0,SUM(E18,E19),IF(ISNUMBER(E20),E20,0)) -> 46487 | F14: =SUM(F15,F16,F17)+IF(COUNT(F18,F19)>0,SUM(F18,F19),IF(ISNUMBER(F20),F20,0)) -> 58033 | G14: =SUM(G15,G16,G17)+IF(COUNT(G18,G19)>0,SUM(G18,G19),IF(ISNUMBER(G20),G20,0)) -> 54469 | H14: =SUM(H15,H16,H17)+IF(COUNT(H18,H19)>0,SUM(H18,H19),IF(ISNUMBER(H20),H20,0)) -> 48871 | I14: =SUM(I15,I16,I17)+IF(COUNT(I18,I19)>0,SUM(I18,I19),IF(ISNUMBER(I20),I20,0)) -> 42831 | J14: =SUM(J15,J16,J17)+IF(COUNT(J18,J19)>0,SUM(J18,J19),IF(ISNUMBER(J20),J20,0)) -> 44622 | ... M14: =SUM(M15,M16,M17)+IF(COUNT(M18,M19)>0,SUM(M18,M19),IF(ISNUMBER(M20),M20,0)) -> 51523 | N14: Walmart reports short-term borrowings, LTD due within one year, LTD, and finance (pre-2019: capital) lease obligations as separate balance-sheet lines.
A15: Short-term borrowings | B15: ShortTermBorrowings | C15: 2708 | D15: 1099 | E15: 5257 | F15: 5225 | G15: 575 | H15: 224 | I15: 410 | J15: 372 | K15: 878 | L15: 3068 | M15: 6596 | N15: Debt component.
A16: Long-term debt – due within one year | B16: LongTermDebtCurrent | C16: 2745 | D16: 2256 | E16: 3738 | F16: 1876 | G16: 5362 | H16: 3115 | I16: 2803 | J16: 4191 | K16: 3447 | L16: 2598 | M16: 3542 | N16: Debt component.
A17: Long-term debt – non-current | B17: LongTermDebtNoncurrent | C17: 38214 | D17: 36015 | E17: 30045 | F17: 43520 | G17: 43714 | H17: 41194 | I17: 34864 | J17: 34649 | K17: 36132 | L17: 33401 | M17: 34624 | N17: Debt component.
A18: Finance / capital lease liability – current | B18: CapitalLeaseObligationsCurrent; FinanceLeaseLiabilityCurrent | C18: 551 | D18: 565 | E18: 667 | F18: 729 | G18: 511 | H18: 491 | I18: 511 | J18: 567 | K18: 725 | L18: 800 | M18: 856 | N18: Debt component.
A19: Finance / capital lease liability – non-current | B19: CapitalLeaseObligationsNoncurrent; FinanceLeaseLiabilityNoncurrent | C19: 5816 | D19: 6003 | E19: 6780 | F19: 6683 | G19: 4307 | H19: 3847 | I19: 4243 | J19: 4843 | K19: 5709 | L19: 5923 | M19: 5905 | N19: Debt component.
A20: Finance lease liability – total (years not split on the balance sheet) | B20: CapitalLeaseObligations; FinanceLeaseLiability | C20: 6367 | D20: 6568 | E20: 7447 | F20: 7412 | G20: 4818 | H20: 4338 | I20: 4754 | J20: 5410 | K20: 6434 | L20: 6723 | M20: 6761 | N20: Debt component.
A21: Operating income (memo) | B21: OperatingIncomeLoss | C21: 24105 | D21: 22764 | E21: 20437 | F21: 21957 | G21: 20568 | H21: 22548 | I21: 25942 | J21: 20428 | K21: 27012 | L21: 29348 | M21: 29825 | N21: Memo item – not used in the five core ratios except where stated.
A22: Operating lease liability (ASC 842; excluded from Total debt) (memo) | B22: OperatingLeaseLiability; OperatingLeaseLiabilityNoncurrent | C22: n/a | D22: n/a | E22: n/a | F22: n/a | G22: 17964 | H22: 14375 | I22: 14492 | J22: 14301 | K22: 14430 | L22: 14324 | M22: 15572 | N22: Memo item – not used in the five core ratios except where stated.
A23: Total assets (memo) | B23: Assets | C23: 199581 | D23: 198825 | E23: 204522 | F23: 219295 | G23: 236495 | H23: 252496 | I23: 244860 | J23: 243197 | K23: 252399 | L23: 260823 | M23: 284668 | N23: Memo item – not used in the five core ratios except where stated.
A24: Inventory (memo) | B24: InventoryNet | C24: 44469 | D24: 43046 | E24: 43783 | F24: 44269 | G24: 44435 | H24: 44949 | I24: 56511 | J24: 56576 | K24: 54892 | L24: 56435 | M24: 58851 | N24: Memo item – not used in the five core ratios except where stated.
A26: Costco — Costco Wholesale Corporation, CIK 909832
A27: Fiscal year end | B27: Sunday nearest August 31 | C27: 42246 | D27: 42610 | E27: 42981 | F27: 43345 | G27: 43709 | H27: 44073 | I27: 44437 | J27: 44801 | K27: 45172 | L27: 45536 | M27: 45900
A28: Revenue (net sales) | B28: us-gaap:RevenueFromContractWithCustomerExcludingAssessedTax; us-gaap:SalesRevenueNet | C28: 113666 | D28: 116073 | E28: 126172 | F28: 138434 | G28: 149351 | H28: 163220 | I28: 192052 | J28: 222730 | K28: 237710 | L28: 249625 | M28: 269912 | N28: 10-K XBRL via SEC companyfacts API; latest-filed (restated) value. NET SALES (merchandise), excluding membership fees - ProductOrServiceAxis = ProductMember from FY2018 (parsed from the XBRL instance), SalesRevenueNet before ASC 606. Total revenue is shown as a memo row.
A29: Cost of sales | B29: CostOfGoodsAndServicesSold; CostOfGoodsSold | C29: 101065 | D29: 102901 | E29: 111882 | F29: 123152 | G29: 132886 | H29: 144939 | I29: 170684 | J29: 199382 | K29: 212586 | L29: 222358 | M29: 239886 | N29: 10-K XBRL via SEC companyfacts API; latest-filed (restated) value.
A30: Net income | B30: NetIncomeLoss | C30: 2377 | D30: 2350 | E30: 2679 | F30: 3134 | G30: 3659 | H30: 4002 | I30: 5007 | J30: 5844 | K30: 6292 | L30: 7367 | M30: 8099 | N30: 10-K XBRL via SEC companyfacts API; latest-filed (restated) value. Attributable to the parent (NetIncomeLoss).
A31: Current assets | B31: AssetsCurrent | C31: 16779 | D31: 15218 | E31: 17317 | F31: 20289 | G31: 23485 | H31: 28120 | I31: 29505 | J31: 32696 | K31: 35879 | L31: 34246 | M31: 38380 | N31: 10-K XBRL via SEC companyfacts API; latest-filed (restated) value.
A32: Current liabilities | B32: LiabilitiesCurrent | C32: 16539 | D32: 15575 | E32: 17495 | F32: 19926 | G32: 23237 | H32: 24844 | I32: 29441 | J32: 31998 | K32: 33583 | L32: 35464 | M32: 37108 | N32: 10-K XBRL via SEC companyfacts API; latest-filed (restated) value.
A33: Total equity (incl. noncontrolling interest) | B33: StockholdersEquityIncludingPortionAttributableToNoncontrollingInterest | C33: 10843 | D33: 12332 | E33: 11079 | F33: 13103 | G33: 15584 | H33: 18705 | I33: 18078 | J33: 20647 | K33: 25058 | L33: 23622 | M33: 29164 | N33: 10-K XBRL via SEC companyfacts API; latest-filed (restated) value.
A34: Total debt (formula – see debt build below) | B34: Policy: config/debt_policy.yaml (ASC 842) | C34: =SUM(C35,C36)+IF(COUNT(C37,C38)>0,SUM(C37,C38),IF(ISNUMBER(C39),C39,0)) -> 6431 | D34: =SUM(D35,D36)+IF(COUNT(D37,D38)>0,SUM(D37,D38),IF(ISNUMBER(D39),D39,0)) -> 5535 | E34: =SUM(E35,E36)+IF(COUNT(E37,E38)>0,SUM(E37,E38),IF(ISNUMBER(E39),E39,0)) -> 7039 | F34: =SUM(F35,F36)+IF(COUNT(F37,F38)>0,SUM(F37,F38),IF(ISNUMBER(F39),F39,0)) -> 6974 | G34: =SUM(G35,G36)+IF(COUNT(G37,G38)>0,SUM(G37,G38),IF(ISNUMBER(G39),G39,0)) -> 7244 | H34: =SUM(H35,H36)+IF(COUNT(H37,H38)>0,SUM(H37,H38),IF(ISNUMBER(H39),H39,0)) -> 8297 | I34: =SUM(I35,I36)+IF(COUNT(I37,I38)>0,SUM(I37,I38),IF(ISNUMBER(I39),I39,0)) -> 8543 | J34: =SUM(J35,J36)+IF(COUNT(J37,J38)>0,SUM(J37,J38),IF(ISNUMBER(J39),J39,0)) -> 8185 | ... M34: =SUM(M35,M36)+IF(COUNT(M37,M38)>0,SUM(M37,M38),IF(ISNUMBER(M39),M39,0)) -> 7267 | N34: Costco has no short-term borrowings line. Finance leases sit inside 'other current' / 'other long-term liabilities' and are disclosed in the Leases note. finance_lease_total is used only in years where current/non-current are not separately tagged (FY2021-FY2023); the workbook formula takes current+non-current if present, else total.
A35: Long-term debt – due within one year | B35: LongTermDebtCurrent | C35: 1283 | D35: 1100 | E35: 86 | F35: 90 | G35: 1699 | H35: 95 | I35: 799 | J35: 73 | K35: 1081 | L35: 103 | M35: 75 | N35: Debt component.
A36: Long-term debt – non-current | B36: LongTermDebtNoncurrent | C36: 4852 | D36: 4061 | E36: 6573 | F36: 6487 | G36: 5124 | H36: 7514 | I36: 6692 | J36: 6484 | K36: 5377 | L36: 5794 | M36: 5713 | N36: Debt component.
A37: Finance / capital lease liability – current | B37: CapitalLeaseObligationsCurrent; FinanceLeaseLiabilityCurrent | C37: 10 | D37: 10 | E37: 7 | F37: 7 | G37: 26 | H37: 31 | I37: n/a | J37: n/a | K37: n/a | L37: 147 | M37: 78 | N37: Debt component. FY2019: instance – Tagged in the FY2019 10-K XBRL instance (cost-20190901.xml, context FI2019Q4) but absent from the companyfacts API; ASC 840 capital lease, pre-842 adoption.
A38: Finance / capital lease liability – non-current | B38: CapitalLeaseObligationsNoncurrent; FinanceLeaseLiabilityNoncurrent | C38: 286 | D38: 364 | E38: 373 | F38: 390 | G38: 395 | H38: 657 | I38: n/a | J38: n/a | K38: n/a | L38: 1351 | M38: 1401 | N38: Debt component. FY2019: instance – Tagged in the FY2019 10-K XBRL instance (cost-20190901.xml, context FI2019Q4) but absent from the companyfacts API; ties to CapitalLeasesFutureMinimumPaymentsPresentValueOfNetMinimumPayments 421M.
A39: Finance lease liability – total (years not split on the balance sheet) | B39: FinanceLeaseLiability; FinanceLeaseLiabilityPaymentsDue - FinanceLeaseLiabilityUndiscountedExcessAmount | C39: n/a | D39: n/a | E39: n/a | F39: n/a | G39: n/a | H39: 688 | I39: 1052 | J39: 1628 | K39: 1432 | L39: n/a | M39: 1479 | N39: Debt component. FY2022: derived – Finance lease liability not tagged as a balance; derived as undiscounted payments less imputed interest (both us-gaap tagged, Leases note). Costco carries finance leases inside other current / other long-term liabilities. FY2023: derived – Same derivation as FY2022; ties to cost:OperatingLeaseandFinanceLeaseLiabilities 4078M less OperatingLeaseLiability 2646M = 1432M in the same filing.
A40: Operating income (memo) | B40: OperatingIncomeLoss | C40: 3624 | D40: 3672 | E40: 4111 | F40: 4480 | G40: 4737 | H40: 5435 | I40: 6708 | J40: 7793 | K40: 8114 | L40: 9285 | M40: 10383 | N40: Memo item – not used in the five core ratios except where stated.
A41: Operating lease liability (ASC 842; excluded from Total debt) (memo) | B41: OperatingLeaseLiability; OperatingLeaseLiabilityNoncurrent | C41: n/a | D41: n/a | E41: n/a | F41: n/a | G41: n/a | H41: 2789 | I41: 2864 | J41: 2721 | K41: 2646 | L41: 2554 | M41: 2668 | N41: Memo item – not used in the five core ratios except where stated.
A42: Total assets (memo) | B42: Assets | C42: 33017 | D42: 33163 | E42: 36347 | F42: 40830 | G42: 45400 | H42: 55556 | I42: 59268 | J42: 64166 | K42: 68994 | L42: 69831 | M42: 77099 | N42: Memo item – not used in the five core ratios except where stated.
...

Sheet Ratio Calculations
A1: 04 — RATIO CALCULATIONS | M1: COMPETITOR SCORECARD · FY2016–FY2025 · SEC 10-K DATA
A2: Ratio Calculations
A3: Live formulas over named ranges: every cell is =IFERROR( … XLOOKUP(year, Years, Company_Metric) … , "n/a"). Nothing is typed in. Δ columns are percentage-point (margins, growth) or turns (ratios) changes.
A4: Company | B4: 2016 | C4: 2017 | D4: 2018 | E4: 2019 | F4: 2020 | G4: 2021 | H4: 2022 | I4: 2023 | J4: 2024 | K4: 2025 | L4: Δ FY16→FY25 | M4: Δ FY19→FY23 | N4: Formula (FY2025 cell shown)
A6: Gross profit margin — (Revenue − Cost of sales) / Revenue
A7: Walmart | B7: =IFERROR((_xlfn.XLOOKUP(B$4,Years,Walmart_Revenue)-_xlfn.XLOOKUP(B$4,Years,Walmart_COGS))/_xlfn.XLOOKUP(B$4,Years,Walmart_Revenue),"n/a") -> 0.24944267 | C7: =IFERROR((_xlfn.XLOOKUP(C$4,Years,Walmart_Revenue)-_xlfn.XLOOKUP(C$4,Years,Walmart_COGS))/_xlfn.XLOOKUP(C$4,Years,Walmart_Revenue),"n/a") -> 0.24682256 | D7: =IFERROR((_xlfn.XLOOKUP(D$4,Years,Walmart_Revenue)-_xlfn.XLOOKUP(D$4,Years,Walmart_COGS))/_xlfn.XLOOKUP(D$4,Years,Walmart_Revenue),"n/a") -> 0.2449949 | E7: =IFERROR((_xlfn.XLOOKUP(E$4,Years,Walmart_Revenue)-_xlfn.XLOOKUP(E$4,Years,Walmart_COGS))/_xlfn.XLOOKUP(E$4,Years,Walmart_Revenue),"n/a") -> 0.24103622 | F7: =IFERROR((_xlfn.XLOOKUP(F$4,Years,Walmart_Revenue)-_xlfn.XLOOKUP(F$4,Years,Walmart_COGS))/_xlfn.XLOOKUP(F$4,Years,Walmart_Revenue),"n/a") -> 0.24299348 | G7: =IFERROR((_xlfn.XLOOKUP(G$4,Years,Walmart_Revenue)-_xlfn.XLOOKUP(G$4,Years,Walmart_COGS))/_xlfn.XLOOKUP(G$4,Years,Walmart_Revenue),"n/a") -> 0.2444017 | H7: =IFERROR((_xlfn.XLOOKUP(H$4,Years,Walmart_Revenue)-_xlfn.XLOOKUP(H$4,Years,Walmart_COGS))/_xlfn.XLOOKUP(H$4,Years,Walmart_Revenue),"n/a") -> 0.23463353 | I7: =IFERROR((_xlfn.XLOOKUP(I$4,Years,Walmart_Revenue)-_xlfn.XLOOKUP(I$4,Years,Walmart_COGS))/_xlfn.XLOOKUP(I$4,Years,Walmart_Revenue),"n/a") -> 0.23729571 | ... K7: =IFERROR((_xlfn.XLOOKUP(K$4,Years,Walmart_Revenue)-_xlfn.XLOOKUP(K$4,Years,Walmart_COGS))/_xlfn.XLOOKUP(K$4,Years,Walmart_Revenue),"n/a") -> 0.24209351 | L7: =IFERROR(K7-B7,"n/a") -> -0.0073491688 | M7: =IFERROR(I7-E7,"n/a") -> -0.0037405193 | N7: =IFERROR((_xludf.XLOOKUP(K$4,Years,Walmart_Revenue)-_xludf.XLOOKUP(K$4,Years,Walmart_COGS))/_xludf.XLOOKUP(K$4,Years,Walmart_Revenue),"n/a") -> n/a
A8: Costco | B8: =IFERROR((_xlfn.XLOOKUP(B$4,Years,Costco_Revenue)-_xlfn.XLOOKUP(B$4,Years,Costco_COGS))/_xlfn.XLOOKUP(B$4,Years,Costco_Revenue),"n/a") -> 0.11348031 | C8: =IFERROR((_xlfn.XLOOKUP(C$4,Years,Costco_Revenue)-_xlfn.XLOOKUP(C$4,Years,Costco_COGS))/_xlfn.XLOOKUP(C$4,Years,Costco_Revenue),"n/a") -> 0.11325809 | D8: =IFERROR((_xlfn.XLOOKUP(D$4,Years,Costco_Revenue)-_xlfn.XLOOKUP(D$4,Years,Costco_COGS))/_xlfn.XLOOKUP(D$4,Years,Costco_Revenue),"n/a") -> 0.11039196 | E8: =IFERROR((_xlfn.XLOOKUP(E$4,Years,Costco_Revenue)-_xlfn.XLOOKUP(E$4,Years,Costco_COGS))/_xlfn.XLOOKUP(E$4,Years,Costco_Revenue),"n/a") -> 0.11024365 | F8: =IFERROR((_xlfn.XLOOKUP(F$4,Years,Costco_Revenue)-_xlfn.XLOOKUP(F$4,Years,Costco_COGS))/_xlfn.XLOOKUP(F$4,Years,Costco_Revenue),"n/a") -> 0.11200221 | G8: =IFERROR((_xlfn.XLOOKUP(G$4,Years,Costco_Revenue)-_xlfn.XLOOKUP(G$4,Years,Costco_COGS))/_xlfn.XLOOKUP(G$4,Years,Costco_Revenue),"n/a") -> 0.11126153 | H8: =IFERROR((_xlfn.XLOOKUP(H$4,Years,Costco_Revenue)-_xlfn.XLOOKUP(H$4,Years,Costco_COGS))/_xlfn.XLOOKUP(H$4,Years,Costco_Revenue),"n/a") -> 0.10482647 | I8: =IFERROR((_xlfn.XLOOKUP(I$4,Years,Costco_Revenue)-_xlfn.XLOOKUP(I$4,Years,Costco_COGS))/_xlfn.XLOOKUP(I$4,Years,Costco_Revenue),"n/a") -> 0.10569181 | ... K8: =IFERROR((_xlfn.XLOOKUP(K$4,Years,Costco_Revenue)-_xlfn.XLOOKUP(K$4,Years,Costco_COGS))/_xlfn.XLOOKUP(K$4,Years,Costco_Revenue),"n/a") -> 0.11124366 | L8: =IFERROR(K8-B8,"n/a") -> -0.0022366452 | M8: =IFERROR(I8-E8,"n/a") -> -0.0045518449 | N8: =IFERROR((_xludf.XLOOKUP(K$4,Years,Costco_Revenue)-_xludf.XLOOKUP(K$4,Years,Costco_COGS))/_xludf.XLOOKUP(K$4,Years,Costco_Revenue),"n/a") -> n/a
A9: Kroger | B9: =IFERROR((_xlfn.XLOOKUP(B$4,Years,Kroger_Revenue)-_xlfn.XLOOKUP(B$4,Years,Kroger_COGS))/_xlfn.XLOOKUP(B$4,Years,Kroger_Revenue),"n/a") -> 0.22399577 | C9: =IFERROR((_xlfn.XLOOKUP(C$4,Years,Kroger_Revenue)-_xlfn.XLOOKUP(C$4,Years,Kroger_COGS))/_xlfn.XLOOKUP(C$4,Years,Kroger_Revenue),"n/a") -> 0.22281798 | D9: =IFERROR((_xlfn.XLOOKUP(D$4,Years,Kroger_Revenue)-_xlfn.XLOOKUP(D$4,Years,Kroger_COGS))/_xlfn.XLOOKUP(D$4,Years,Kroger_Revenue),"n/a") -> 0.2195204 | E9: =IFERROR((_xlfn.XLOOKUP(E$4,Years,Kroger_Revenue)-_xlfn.XLOOKUP(E$4,Years,Kroger_COGS))/_xlfn.XLOOKUP(E$4,Years,Kroger_Revenue),"n/a") -> 0.22072846 | F9: =IFERROR((_xlfn.XLOOKUP(F$4,Years,Kroger_Revenue)-_xlfn.XLOOKUP(F$4,Years,Kroger_COGS))/_xlfn.XLOOKUP(F$4,Years,Kroger_Revenue),"n/a") -> 0.23321861 | G9: =IFERROR((_xlfn.XLOOKUP(G$4,Years,Kroger_Revenue)-_xlfn.XLOOKUP(G$4,Years,Kroger_COGS))/_xlfn.XLOOKUP(G$4,Years,Kroger_Revenue),"n/a") -> 0.22009892 | H9: =IFERROR((_xlfn.XLOOKUP(H$4,Years,Kroger_Revenue)-_xlfn.XLOOKUP(H$4,Years,Kroger_COGS))/_xlfn.XLOOKUP(H$4,Years,Kroger_Revenue),"n/a") -> 0.21434256 | I9: =IFERROR((_xlfn.XLOOKUP(I$4,Years,Kroger_Revenue)-_xlfn.XLOOKUP(I$4,Years,Kroger_COGS))/_xlfn.XLOOKUP(I$4,Years,Kroger_Revenue),"n/a") -> 0.22236885 | ... K9: =IFERROR((_xlfn.XLOOKUP(K$4,Years,Kroger_Revenue)-_xlfn.XLOOKUP(K$4,Years,Kroger_COGS))/_xlfn.XLOOKUP(K$4,Years,Kroger_Revenue),"n/a") -> 0.23300958 | L9: =IFERROR(K9-B9,"n/a") -> 0.0090138083 | M9: =IFERROR(I9-E9,"n/a") -> 0.0016403945 | N9: =IFERROR((_xludf.XLOOKUP(K$4,Years,Kroger_Revenue)-_xludf.XLOOKUP(K$4,Years,Kroger_COGS))/_xludf.XLOOKUP(K$4,Years,Kroger_Revenue),"n/a") -> n/a
A10: Sam's Club | B10: =IFERROR((_xlfn.XLOOKUP(B$4,Years,SamsClub_Revenue)-_xlfn.XLOOKUP(B$4,Years,SamsClub_COGS))/_xlfn.XLOOKUP(B$4,Years,SamsClub_Revenue),"n/a") -> n/a | C10: =IFERROR((_xlfn.XLOOKUP(C$4,Years,SamsClub_Revenue)-_xlfn.XLOOKUP(C$4,Years,SamsClub_COGS))/_xlfn.XLOOKUP(C$4,Years,SamsClub_Revenue),"n/a") -> n/a | D10: =IFERROR((_xlfn.XLOOKUP(D$4,Years,SamsClub_Revenue)-_xlfn.XLOOKUP(D$4,Years,SamsClub_COGS))/_xlfn.XLOOKUP(D$4,Years,SamsClub_Revenue),"n/a") -> n/a | E10: =IFERROR((_xlfn.XLOOKUP(E$4,Years,SamsClub_Revenue)-_xlfn.XLOOKUP(E$4,Years,SamsClub_COGS))/_xlfn.XLOOKUP(E$4,Years,SamsClub_Revenue),"n/a") -> n/a | F10: =IFERROR((_xlfn.XLOOKUP(F$4,Years,SamsClub_Revenue)-_xlfn.XLOOKUP(F$4,Years,SamsClub_COGS))/_xlfn.XLOOKUP(F$4,Years,SamsClub_Revenue),"n/a") -> n/a | G10: =IFERROR((_xlfn.XLOOKUP(G$4,Years,SamsClub_Revenue)-_xlfn.XLOOKUP(G$4,Years,SamsClub_COGS))/_xlfn.XLOOKUP(G$4,Years,SamsClub_Revenue),"n/a") -> n/a | H10: =IFERROR((_xlfn.XLOOKUP(H$4,Years,SamsClub_Revenue)-_xlfn.XLOOKUP(H$4,Years,SamsClub_COGS))/_xlfn.XLOOKUP(H$4,Years,SamsClub_Revenue),"n/a") -> 0.10387101 | I10: =IFERROR((_xlfn.XLOOKUP(I$4,Years,SamsClub_Revenue)-_xlfn.XLOOKUP(I$4,Years,SamsClub_COGS))/_xlfn.XLOOKUP(I$4,Years,SamsClub_Revenue),"n/a") -> 0.10943501 | ... K10: =IFERROR((_xlfn.XLOOKUP(K$4,Years,SamsClub_Revenue)-_xlfn.XLOOKUP(K$4,Years,SamsClub_COGS))/_xlfn.XLOOKUP(K$4,Years,SamsClub_Revenue),"n/a") -> 0.11348707 | L10: =IFERROR(K10-B10,"n/a") -> n/a | M10: =IFERROR(I10-E10,"n/a") -> n/a | N10: =IFERROR((_xludf.XLOOKUP(K$4,Years,SamsClub_Revenue)-_xludf.XLOOKUP(K$4,Years,SamsClub_COGS))/_xludf.XLOOKUP(K$4,Years,SamsClub_Revenue),"n/a") -> n/a
A11: Whole Foods | B11: =IFERROR((_xlfn.XLOOKUP(B$4,Years,WholeFoods_Revenue)-_xlfn.XLOOKUP(B$4,Years,WholeFoods_COGS))/_xlfn.XLOOKUP(B$4,Years,WholeFoods_Revenue),"n/a") -> 0.34412363 | C11: =IFERROR((_xlfn.XLOOKUP(C$4,Years,WholeFoods_Revenue)-_xlfn.XLOOKUP(C$4,Years,WholeFoods_COGS))/_xlfn.XLOOKUP(C$4,Years,WholeFoods_Revenue),"n/a") -> 0.33668122 | D11: =IFERROR((_xlfn.XLOOKUP(D$4,Years,WholeFoods_Revenue)-_xlfn.XLOOKUP(D$4,Years,WholeFoods_COGS))/_xlfn.XLOOKUP(D$4,Years,WholeFoods_Revenue),"n/a") -> n/a | E11: =IFERROR((_xlfn.XLOOKUP(E$4,Years,WholeFoods_Revenue)-_xlfn.XLOOKUP(E$4,Years,WholeFoods_COGS))/_xlfn.XLOOKUP(E$4,Years,WholeFoods_Revenue),"n/a") -> n/a | F11: =IFERROR((_xlfn.XLOOKUP(F$4,Years,WholeFoods_Revenue)-_xlfn.XLOOKUP(F$4,Years,WholeFoods_COGS))/_xlfn.XLOOKUP(F$4,Years,WholeFoods_Revenue),"n/a") -> n/a | G11: =IFERROR((_xlfn.XLOOKUP(G$4,Years,WholeFoods_Revenue)-_xlfn.XLOOKUP(G$4,Years,WholeFoods_COGS))/_xlfn.XLOOKUP(G$4,Years,WholeFoods_Revenue),"n/a") -> n/a | H11: =IFERROR((_xlfn.XLOOKUP(H$4,Years,WholeFoods_Revenue)-_xlfn.XLOOKUP(H$4,Years,WholeFoods_COGS))/_xlfn.XLOOKUP(H$4,Years,WholeFoods_Revenue),"n/a") -> n/a | I11: =IFERROR((_xlfn.XLOOKUP(I$4,Years,WholeFoods_Revenue)-_xlfn.XLOOKUP(I$4,Years,WholeFoods_COGS))/_xlfn.XLOOKUP(I$4,Years,WholeFoods_Revenue),"n/a") -> n/a | ... K11: =IFERROR((_xlfn.XLOOKUP(K$4,Years,WholeFoods_Revenue)-_xlfn.XLOOKUP(K$4,Years,WholeFoods_COGS))/_xlfn.XLOOKUP(K$4,Years,WholeFoods_Revenue),"n/a") -> n/a | L11: =IFERROR(K11-B11,"n/a") -> n/a | M11: =IFERROR(I11-E11,"n/a") -> n/a | N11: =IFERROR((_xludf.XLOOKUP(K$4,Years,WholeFoods_Revenue)-_xludf.XLOOKUP(K$4,Years,WholeFoods_COGS))/_xludf.XLOOKUP(K$4,Years,WholeFoods_Revenue),"n/a") -> n/a
A13: Operating margin (supplementary) — Operating income / Revenue – separates gross-margin pressure from SG&A
A14: Walmart | B14: =IFERROR(_xlfn.XLOOKUP(B$4,Years,Walmart_OperatingIncome)/_xlfn.XLOOKUP(B$4,Years,Walmart_Revenue),"n/a") -> 0.047295234 | C14: =IFERROR(_xlfn.XLOOKUP(C$4,Years,Walmart_OperatingIncome)/_xlfn.XLOOKUP(C$4,Years,Walmart_Revenue),"n/a") -> 0.041223493 | D14: =IFERROR(_xlfn.XLOOKUP(D$4,Years,Walmart_OperatingIncome)/_xlfn.XLOOKUP(D$4,Years,Walmart_Revenue),"n/a") -> 0.043025186 | E14: =IFERROR(_xlfn.XLOOKUP(E$4,Years,Walmart_OperatingIncome)/_xlfn.XLOOKUP(E$4,Years,Walmart_Revenue),"n/a") -> 0.039559476 | F14: =IFERROR(_xlfn.XLOOKUP(F$4,Years,Walmart_OperatingIncome)/_xlfn.XLOOKUP(F$4,Years,Walmart_Revenue),"n/a") -> 0.040609978 | G14: =IFERROR(_xlfn.XLOOKUP(G$4,Years,Walmart_OperatingIncome)/_xlfn.XLOOKUP(G$4,Years,Walmart_Revenue),"n/a") -> 0.045691681 | H14: =IFERROR(_xlfn.XLOOKUP(H$4,Years,Walmart_OperatingIncome)/_xlfn.XLOOKUP(H$4,Years,Walmart_Revenue),"n/a") -> 0.033716192 | I14: =IFERROR(_xlfn.XLOOKUP(I$4,Years,Walmart_OperatingIncome)/_xlfn.XLOOKUP(I$4,Years,Walmart_Revenue),"n/a") -> 0.042033061 | ... K14: =IFERROR(_xlfn.XLOOKUP(K$4,Years,Walmart_OperatingIncome)/_xlfn.XLOOKUP(K$4,Years,Walmart_Revenue),"n/a") -> 0.042220344 | L14: =IFERROR(K14-B14,"n/a") -> -0.0050748895 | M14: =IFERROR(I14-E14,"n/a") -> 0.0024735849 | N14: =IFERROR(_xludf.XLOOKUP(K$4,Years,Walmart_OperatingIncome)/_xludf.XLOOKUP(K$4,Years,Walmart_Revenue),"n/a") -> n/a
A15: Costco | B15: =IFERROR(_xlfn.XLOOKUP(B$4,Years,Costco_OperatingIncome)/_xlfn.XLOOKUP(B$4,Years,Costco_Revenue),"n/a") -> 0.031635264 | C15: =IFERROR(_xlfn.XLOOKUP(C$4,Years,Costco_OperatingIncome)/_xlfn.XLOOKUP(C$4,Years,Costco_Revenue),"n/a") -> 0.032582506 | D15: =IFERROR(_xlfn.XLOOKUP(D$4,Years,Costco_OperatingIncome)/_xlfn.XLOOKUP(D$4,Years,Costco_Revenue),"n/a") -> 0.032361992 | E15: =IFERROR(_xlfn.XLOOKUP(E$4,Years,Costco_OperatingIncome)/_xlfn.XLOOKUP(E$4,Years,Costco_Revenue),"n/a") -> 0.03171723 | F15: =IFERROR(_xlfn.XLOOKUP(F$4,Years,Costco_OperatingIncome)/_xlfn.XLOOKUP(F$4,Years,Costco_Revenue),"n/a") -> 0.033298615 | G15: =IFERROR(_xlfn.XLOOKUP(G$4,Years,Costco_OperatingIncome)/_xlfn.XLOOKUP(G$4,Years,Costco_Revenue),"n/a") -> 0.03492804 | H15: =IFERROR(_xlfn.XLOOKUP(H$4,Years,Costco_OperatingIncome)/_xlfn.XLOOKUP(H$4,Years,Costco_Revenue),"n/a") -> 0.034988551 | I15: =IFERROR(_xlfn.XLOOKUP(I$4,Years,Costco_OperatingIncome)/_xlfn.XLOOKUP(I$4,Years,Costco_Revenue),"n/a") -> 0.034134029 | ... K15: =IFERROR(_xlfn.XLOOKUP(K$4,Years,Costco_OperatingIncome)/_xlfn.XLOOKUP(K$4,Years,Costco_Revenue),"n/a") -> 0.038468093 | L15: =IFERROR(K15-B15,"n/a") -> 0.0068328293 | M15: =IFERROR(I15-E15,"n/a") -> 0.002416799 | N15: =IFERROR(_xludf.XLOOKUP(K$4,Years,Costco_OperatingIncome)/_xludf.XLOOKUP(K$4,Years,Costco_Revenue),"n/a") -> n/a
A16: Kroger | B16: =IFERROR(_xlfn.XLOOKUP(B$4,Years,Kroger_OperatingIncome)/_xlfn.XLOOKUP(B$4,Years,Kroger_Revenue),"n/a") -> 0.029929684 | C16: =IFERROR(_xlfn.XLOOKUP(C$4,Years,Kroger_OperatingIncome)/_xlfn.XLOOKUP(C$4,Years,Kroger_Revenue),"n/a") -> 0.021187541 | D16: =IFERROR(_xlfn.XLOOKUP(D$4,Years,Kroger_OperatingIncome)/_xlfn.XLOOKUP(D$4,Years,Kroger_Revenue),"n/a") -> 0.021452254 | E16: =IFERROR(_xlfn.XLOOKUP(E$4,Years,Kroger_OperatingIncome)/_xlfn.XLOOKUP(E$4,Years,Kroger_Revenue),"n/a") -> 0.018407667 | F16: =IFERROR(_xlfn.XLOOKUP(F$4,Years,Kroger_OperatingIncome)/_xlfn.XLOOKUP(F$4,Years,Kroger_Revenue),"n/a") -> 0.020981449 | G16: =IFERROR(_xlfn.XLOOKUP(G$4,Years,Kroger_OperatingIncome)/_xlfn.XLOOKUP(G$4,Years,Kroger_Revenue),"n/a") -> 0.025216117 | H16: =IFERROR(_xlfn.XLOOKUP(H$4,Years,Kroger_OperatingIncome)/_xlfn.XLOOKUP(H$4,Years,Kroger_Revenue),"n/a") -> 0.027829864 | I16: =IFERROR(_xlfn.XLOOKUP(I$4,Years,Kroger_OperatingIncome)/_xlfn.XLOOKUP(I$4,Years,Kroger_Revenue),"n/a") -> 0.020634635 | ... K16: =IFERROR(_xlfn.XLOOKUP(K$4,Years,Kroger_OperatingIncome)/_xlfn.XLOOKUP(K$4,Years,Kroger_Revenue),"n/a") -> 0.012801235 | L16: =IFERROR(K16-B16,"n/a") -> -0.017128449 | M16: =IFERROR(I16-E16,"n/a") -> 0.0022269677 | N16: =IFERROR(_xludf.XLOOKUP(K$4,Years,Kroger_OperatingIncome)/_xludf.XLOOKUP(K$4,Years,Kroger_Revenue),"n/a") -> n/a
A17: Sam's Club | B17: =IFERROR(_xlfn.XLOOKUP(B$4,Years,SamsClub_OperatingIncome)/_xlfn.XLOOKUP(B$4,Years,SamsClub_Revenue),"n/a") -> 0.028379674 | C17: =IFERROR(_xlfn.XLOOKUP(C$4,Years,SamsClub_OperatingIncome)/_xlfn.XLOOKUP(C$4,Years,SamsClub_Revenue),"n/a") -> 0.015451905 | D17: =IFERROR(_xlfn.XLOOKUP(D$4,Years,SamsClub_OperatingIncome)/_xlfn.XLOOKUP(D$4,Years,SamsClub_Revenue),"n/a") -> 0.026279846 | E17: =IFERROR(_xlfn.XLOOKUP(E$4,Years,SamsClub_OperatingIncome)/_xlfn.XLOOKUP(E$4,Years,SamsClub_Revenue),"n/a") -> 0.02792897 | F17: =IFERROR(_xlfn.XLOOKUP(F$4,Years,SamsClub_OperatingIncome)/_xlfn.XLOOKUP(F$4,Years,SamsClub_Revenue),"n/a") -> 0.029823189 | G17: =IFERROR(_xlfn.XLOOKUP(G$4,Years,SamsClub_OperatingIncome)/_xlfn.XLOOKUP(G$4,Years,SamsClub_Revenue),"n/a") -> 0.030711295 | H17: =IFERROR(_xlfn.XLOOKUP(H$4,Years,SamsClub_OperatingIncome)/_xlfn.XLOOKUP(H$4,Years,SamsClub_Revenue),"n/a") -> 0.023285316 | I17: =IFERROR(_xlfn.XLOOKUP(I$4,Years,SamsClub_OperatingIncome)/_xlfn.XLOOKUP(I$4,Years,SamsClub_Revenue),"n/a") -> 0.025435431 | ... K17: =IFERROR(_xlfn.XLOOKUP(K$4,Years,SamsClub_OperatingIncome)/_xlfn.XLOOKUP(K$4,Years,SamsClub_Revenue),"n/a") -> 0.02625383 | L17: =IFERROR(K17-B17,"n/a") -> -0.002125844 | M17: =IFERROR(I17-E17,"n/a") -> -0.002493539 | N17: =IFERROR(_xludf.XLOOKUP(K$4,Years,SamsClub_OperatingIncome)/_xludf.XLOOKUP(K$4,Years,SamsClub_Revenue),"n/a") -> n/a
A18: Whole Foods | B18: =IFERROR(_xlfn.XLOOKUP(B$4,Years,WholeFoods_OperatingIncome)/_xlfn.XLOOKUP(B$4,Years,WholeFoods_Revenue),"n/a") -> 0.054502671 | C18: =IFERROR(_xlfn.XLOOKUP(C$4,Years,WholeFoods_OperatingIncome)/_xlfn.XLOOKUP(C$4,Years,WholeFoods_Revenue),"n/a") -> 0.028633812 | D18: =IFERROR(_xlfn.XLOOKUP(D$4,Years,WholeFoods_OperatingIncome)/_xlfn.XLOOKUP(D$4,Years,WholeFoods_Revenue),"n/a") -> n/a | E18: =IFERROR(_xlfn.XLOOKUP(E$4,Years,WholeFoods_OperatingIncome)/_xlfn.XLOOKUP(E$4,Years,WholeFoods_Revenue),"n/a") -> n/a | F18: =IFERROR(_xlfn.XLOOKUP(F$4,Years,WholeFoods_OperatingIncome)/_xlfn.XLOOKUP(F$4,Years,WholeFoods_Revenue),"n/a") -> n/a | G18: =IFERROR(_xlfn.XLOOKUP(G$4,Years,WholeFoods_OperatingIncome)/_xlfn.XLOOKUP(G$4,Years,WholeFoods_Revenue),"n/a") -> n/a | H18: =IFERROR(_xlfn.XLOOKUP(H$4,Years,WholeFoods_OperatingIncome)/_xlfn.XLOOKUP(H$4,Years,WholeFoods_Revenue),"n/a") -> n/a | I18: =IFERROR(_xlfn.XLOOKUP(I$4,Years,WholeFoods_OperatingIncome)/_xlfn.XLOOKUP(I$4,Years,WholeFoods_Revenue),"n/a") -> n/a | ... K18: =IFERROR(_xlfn.XLOOKUP(K$4,Years,WholeFoods_OperatingIncome)/_xlfn.XLOOKUP(K$4,Years,WholeFoods_Revenue),"n/a") -> n/a | L18: =IFERROR(K18-B18,"n/a") -> n/a | M18: =IFERROR(I18-E18,"n/a") -> n/a | N18: =IFERROR(_xludf.XLOOKUP(K$4,Years,WholeFoods_OperatingIncome)/_xludf.XLOOKUP(K$4,Years,WholeFoods_Revenue),"n/a") -> n/a
A20: Net profit margin — Net income / Revenue
A21: Walmart | B21: =IFERROR(_xlfn.XLOOKUP(B$4,Years,Walmart_NetIncome)/_xlfn.XLOOKUP(B$4,Years,Walmart_Revenue),"n/a") -> 0.028345145 | C21: =IFERROR(_xlfn.XLOOKUP(C$4,Years,Walmart_NetIncome)/_xlfn.XLOOKUP(C$4,Years,Walmart_Revenue),"n/a") -> 0.01989265 | D21: =IFERROR(_xlfn.XLOOKUP(D$4,Years,Walmart_NetIncome)/_xlfn.XLOOKUP(D$4,Years,Walmart_Revenue),"n/a") -> 0.01307 | E21: =IFERROR(_xlfn.XLOOKUP(E$4,Years,Walmart_NetIncome)/_xlfn.XLOOKUP(E$4,Years,Walmart_Revenue),"n/a") -> 0.028621381 | F21: =IFERROR(_xlfn.XLOOKUP(F$4,Years,Walmart_NetIncome)/_xlfn.XLOOKUP(F$4,Years,Walmart_Revenue),"n/a") -> 0.024332127 | G21: =IFERROR(_xlfn.XLOOKUP(G$4,Years,Walmart_NetIncome)/_xlfn.XLOOKUP(G$4,Years,Walmart_Revenue),"n/a") -> 0.024082274 | H21: =IFERROR(_xlfn.XLOOKUP(H$4,Years,Walmart_NetIncome)/_xlfn.XLOOKUP(H$4,Years,Walmart_Revenue),"n/a") -> 0.019277713 | I21: =IFERROR(_xlfn.XLOOKUP(I$4,Years,Walmart_NetIncome)/_xlfn.XLOOKUP(I$4,Years,Walmart_Revenue),"n/a") -> 0.024136488 | ... K21: =IFERROR(_xlfn.XLOOKUP(K$4,Years,Walmart_NetIncome)/_xlfn.XLOOKUP(K$4,Years,Walmart_Revenue),"n/a") -> 0.030991785 | L21: =IFERROR(K21-B21,"n/a") -> 0.0026466406 | M21: =IFERROR(I21-E21,"n/a") -> -0.0044848931 | N21: =IFERROR(_xludf.XLOOKUP(K$4,Years,Walmart_NetIncome)/_xludf.XLOOKUP(K$4,Years,Walmart_Revenue),"n/a") -> n/a
A22: Costco | B22: =IFERROR(_xlfn.XLOOKUP(B$4,Years,Costco_NetIncome)/_xlfn.XLOOKUP(B$4,Years,Costco_Revenue),"n/a") -> 0.02024588 | C22: =IFERROR(_xlfn.XLOOKUP(C$4,Years,Costco_NetIncome)/_xlfn.XLOOKUP(C$4,Years,Costco_Revenue),"n/a") -> 0.02123292 | D22: =IFERROR(_xlfn.XLOOKUP(D$4,Years,Costco_NetIncome)/_xlfn.XLOOKUP(D$4,Years,Costco_Revenue),"n/a") -> 0.022638947 | E22: =IFERROR(_xlfn.XLOOKUP(E$4,Years,Costco_NetIncome)/_xlfn.XLOOKUP(E$4,Years,Costco_Revenue),"n/a") -> 0.024499334 | F22: =IFERROR(_xlfn.XLOOKUP(F$4,Years,Costco_NetIncome)/_xlfn.XLOOKUP(F$4,Years,Costco_Revenue),"n/a") -> 0.024519054 | G22: =IFERROR(_xlfn.XLOOKUP(G$4,Years,Costco_NetIncome)/_xlfn.XLOOKUP(G$4,Years,Costco_Revenue),"n/a") -> 0.026071064 | H22: =IFERROR(_xlfn.XLOOKUP(H$4,Years,Costco_NetIncome)/_xlfn.XLOOKUP(H$4,Years,Costco_Revenue),"n/a") -> 0.026238046 | I22: =IFERROR(_xlfn.XLOOKUP(I$4,Years,Costco_NetIncome)/_xlfn.XLOOKUP(I$4,Years,Costco_Revenue),"n/a") -> 0.026469227 | ... K22: =IFERROR(_xlfn.XLOOKUP(K$4,Years,Costco_NetIncome)/_xlfn.XLOOKUP(K$4,Years,Costco_Revenue),"n/a") -> 0.030006076 | L22: =IFERROR(K22-B22,"n/a") -> 0.0097601963 | M22: =IFERROR(I22-E22,"n/a") -> 0.0019698934 | N22: =IFERROR(_xludf.XLOOKUP(K$4,Years,Costco_NetIncome)/_xludf.XLOOKUP(K$4,Years,Costco_Revenue),"n/a") -> n/a
A23: Kroger | B23: =IFERROR(_xlfn.XLOOKUP(B$4,Years,Kroger_NetIncome)/_xlfn.XLOOKUP(B$4,Years,Kroger_Revenue),"n/a") -> 0.017123733 | C23: =IFERROR(_xlfn.XLOOKUP(C$4,Years,Kroger_NetIncome)/_xlfn.XLOOKUP(C$4,Years,Kroger_Revenue),"n/a") -> 0.015468851 | D23: =IFERROR(_xlfn.XLOOKUP(D$4,Years,Kroger_NetIncome)/_xlfn.XLOOKUP(D$4,Years,Kroger_Revenue),"n/a") -> 0.025522765 | E23: =IFERROR(_xlfn.XLOOKUP(E$4,Years,Kroger_NetIncome)/_xlfn.XLOOKUP(E$4,Years,Kroger_Revenue),"n/a") -> 0.013566557 | F23: =IFERROR(_xlfn.XLOOKUP(F$4,Years,Kroger_NetIncome)/_xlfn.XLOOKUP(F$4,Years,Kroger_Revenue),"n/a") -> 0.019509728 | G23: =IFERROR(_xlfn.XLOOKUP(G$4,Years,Kroger_NetIncome)/_xlfn.XLOOKUP(G$4,Years,Kroger_Revenue),"n/a") -> 0.012002495 | H23: =IFERROR(_xlfn.XLOOKUP(H$4,Years,Kroger_NetIncome)/_xlfn.XLOOKUP(H$4,Years,Kroger_Revenue),"n/a") -> 0.015135777 | I23: =IFERROR(_xlfn.XLOOKUP(I$4,Years,Kroger_NetIncome)/_xlfn.XLOOKUP(I$4,Years,Kroger_Revenue),"n/a") -> 0.014422917 | ... K23: =IFERROR(_xlfn.XLOOKUP(K$4,Years,Kroger_NetIncome)/_xlfn.XLOOKUP(K$4,Years,Kroger_Revenue),"n/a") -> 0.0068815107 | L23: =IFERROR(K23-B23,"n/a") -> -0.010242222 | M23: =IFERROR(I23-E23,"n/a") -> 0.00085635962 | N23: =IFERROR(_xludf.XLOOKUP(K$4,Years,Kroger_NetIncome)/_xludf.XLOOKUP(K$4,Years,Kroger_Revenue),"n/a") -> n/a
A24: Sam's Club | B24: =IFERROR(_xlfn.XLOOKUP(B$4,Years,SamsClub_NetIncome)/_xlfn.XLOOKUP(B$4,Years,SamsClub_Revenue),"n/a") -> n/a | C24: =IFERROR(_xlfn.XLOOKUP(C$4,Years,SamsClub_NetIncome)/_xlfn.XLOOKUP(C$4,Years,SamsClub_Revenue),"n/a") -> n/a | D24: =IFERROR(_xlfn.XLOOKUP(D$4,Years,SamsClub_NetIncome)/_xlfn.XLOOKUP(D$4,Years,SamsClub_Revenue),"n/a") -> n/a | E24: =IFERROR(_xlfn.XLOOKUP(E$4,Years,SamsClub_NetIncome)/_xlfn.XLOOKUP(E$4,Years,SamsClub_Revenue),"n/a") -> n/a | F24: =IFERROR(_xlfn.XLOOKUP(F$4,Years,SamsClub_NetIncome)/_xlfn.XLOOKUP(F$4,Years,SamsClub_Revenue),"n/a") -> n/a | G24: =IFERROR(_xlfn.XLOOKUP(G$4,Years,SamsClub_NetIncome)/_xlfn.XLOOKUP(G$4,Years,SamsClub_Revenue),"n/a") -> n/a | H24: =IFERROR(_xlfn.XLOOKUP(H$4,Years,SamsClub_NetIncome)/_xlfn.XLOOKUP(H$4,Years,SamsClub_Revenue),"n/a") -> n/a | I24: =IFERROR(_xlfn.XLOOKUP(I$4,Years,SamsClub_NetIncome)/_xlfn.XLOOKUP(I$4,Years,SamsClub_Revenue),"n/a") -> n/a | ... K24: =IFERROR(_xlfn.XLOOKUP(K$4,Years,SamsClub_NetIncome)/_xlfn.XLOOKUP(K$4,Years,SamsClub_Revenue),"n/a") -> n/a | L24: =IFERROR(K24-B24,"n/a") -> n/a | M24: =IFERROR(I24-E24,"n/a") -> n/a | N24: =IFERROR(_xludf.XLOOKUP(K$4,Years,SamsClub_NetIncome)/_xludf.XLOOKUP(K$4,Years,SamsClub_Revenue),"n/a") -> n/a
A25: Whole Foods | B25: =IFERROR(_xlfn.XLOOKUP(B$4,Years,WholeFoods_NetIncome)/_xlfn.XLOOKUP(B$4,Years,WholeFoods_Revenue),"n/a") -> 0.032243704 | C25: =IFERROR(_xlfn.XLOOKUP(C$4,Years,WholeFoods_NetIncome)/_xlfn.XLOOKUP(C$4,Years,WholeFoods_Revenue),"n/a") -> 0.015283843 | D25: =IFERROR(_xlfn.XLOOKUP(D$4,Years,WholeFoods_NetIncome)/_xlfn.XLOOKUP(D$4,Years,WholeFoods_Revenue),"n/a") -> n/a | E25: =IFERROR(_xlfn.XLOOKUP(E$4,Years,WholeFoods_NetIncome)/_xlfn.XLOOKUP(E$4,Years,WholeFoods_Revenue),"n/a") -> n/a | F25: =IFERROR(_xlfn.XLOOKUP(F$4,Years,WholeFoods_NetIncome)/_xlfn.XLOOKUP(F$4,Years,WholeFoods_Revenue),"n/a") -> n/a | G25: =IFERROR(_xlfn.XLOOKUP(G$4,Years,WholeFoods_NetIncome)/_xlfn.XLOOKUP(G$4,Years,WholeFoods_Revenue),"n/a") -> n/a | H25: =IFERROR(_xlfn.XLOOKUP(H$4,Years,WholeFoods_NetIncome)/_xlfn.XLOOKUP(H$4,Years,WholeFoods_Revenue),"n/a") -> n/a | I25: =IFERROR(_xlfn.XLOOKUP(I$4,Years,WholeFoods_NetIncome)/_xlfn.XLOOKUP(I$4,Years,WholeFoods_Revenue),"n/a") -> n/a | ... K25: =IFERROR(_xlfn.XLOOKUP(K$4,Years,WholeFoods_NetIncome)/_xlfn.XLOOKUP(K$4,Years,WholeFoods_Revenue),"n/a") -> n/a | L25: =IFERROR(K25-B25,"n/a") -> n/a | M25: =IFERROR(I25-E25,"n/a") -> n/a | N25: =IFERROR(_xludf.XLOOKUP(K$4,Years,WholeFoods_NetIncome)/_xludf.XLOOKUP(K$4,Years,WholeFoods_Revenue),"n/a") -> n/a
A27: Current ratio — Current assets / Current liabilities
